Workbook

Sheet How to review
A1: Ground truth review: baseline v1.1
A3: Why | B3: Aarvin asked how we can trust LLM-generated labels. Each span now has a ground_truth column that you check by hand, one email at a time.
A4: Status | B4: Claude filled ground_truth as a draft. Nothing here is final until you set Karina check on every row.
A5: What to edit | B5: Only the two yellow columns on the Spans sheet: ground_truth (redact or retain) and Karina check (OK or Changed).
A6: ground_truth | B6: redact = sending this raw to the cloud is a leak. retain = public or harmless, the service should leave it.
A7: Fast path | B7: Filter Spans on 'Diff vs v1' first: 15 rows changed and 55 rows added. Then read each email on the Emails sheet and tick the rest.
A8: Notes column | B8: Every row Claude changed or added has a reason. Rows with no note agree with v1.
A9: Schema | B9: Fields, service_type and tier follow the service code: contract 0.4.2 (vg_redactor/contracts/types.py) and policy.yaml 0.1.3. in_policy = FALSE means the type is not in policy.yaml yet (ID_NUMBER, URL).
A10: Source of truth | B10: baseline_v1.1.jsonl. If you change a label here, tell Claude and it will write the change back to the JSONL.
A11: Example row | B11: E002 | email.body | 011000138 | FIN_ACCOUNT | TRUE | ACCOUNT_NUMBER | high | redact | OK

Sheet Summary
A1: Spans total | B1: =COUNTA(Spans!$A$2:$A$1059)
A2: ground_truth = redact | B2: =COUNTIF(Spans!$K$2:$K$1059,"redact")
A3: ground_truth = retain | B3: =COUNTIF(Spans!$K$2:$K$1059,"retain")
A4: Changed vs v1 | B4: =COUNTIF(Spans!$M$2:$M$1059,"changed")
A5: Added in review | B5: =COUNTIF(Spans!$M$2:$M$1059,"added")
A6: Rows Karina checked | B6: =COUNTA(Spans!$L$2:$L$1059)
A7: Rows left to check | B7: =B1-B6
A9: By tier | B9: redact
A10: high | B10: =COUNTIFS(Spans!$I$2:$I$1059,A10,Spans!$K$2:$K$1059,"redact")
A11: medium | B11: =COUNTIFS(Spans!$I$2:$I$1059,A11,Spans!$K$2:$K$1059,"redact")
A12: low | B12: =COUNTIFS(Spans!$I$2:$I$1059,A12,Spans!$K$2:$K$1059,"redact")
A13: public | B13: =COUNTIFS(Spans!$I$2:$I$1059,A13,Spans!$K$2:$K$1059,"redact")

Sheet Spans
A1: Email ID | B1: Area | C1: Field | D1: Span text | E1: Context | F1: v1 label | G1: v1 must_mask | H1: service_type | I1: tier | J1: in_policy | K1: ground_truth | L1: Karina check | M1: Diff vs v1 | N1: Claude note
A2: E001 | B2: Finance & Accounting | C2: email.from.name | D2: Megan Ostrowski | E2: From: [Megan Ostrowski] <m.ostrowski@halvorsenmed.com> To: Vict | F2: PERSON | G2: =TRUE() | H2: PERSON | I2: medium | J2: =TRUE() | K2: redact | M2: =IF(G2="","added",IF((K2="redact")<>G2,"changed",""))
A3: E001 | B3: Finance & Accounting | C3: email.from.address | D3: m.ostrowski@halvorsenmed.com | E3: From: Megan Ostrowski <[m.ostrowski@halvorsenmed.com]> To: Victor Ames <v.ames@halvorsenmed.c | F3: EMAIL | G3: =TRUE() | H3: EMAIL_PERSONAL | I3: medium | J3: =TRUE() | K3: redact | M3: =IF(G3="","added",IF((K3="redact")<>G3,"changed",""))
A4: E001 | B4: Finance & Accounting | C4: email.to[0].name | D4: Victor Ames | E4: wski <m.ostrowski@halvorsenmed.com> To: [Victor Ames] <v.ames@halvorsenmed.com> Subject: Q3 a | F4: PERSON | G4: =TRUE() | H4: PERSON | I4: medium | J4: =TRUE() | K4: redact | M4: =IF(G4="","added",IF((K4="redact")<>G4,"changed",""))
A5: E001 | B5: Finance & Accounting | C5: email.to[0].address | D5: v.ames@halvorsenmed.com | E5: wski@halvorsenmed.com> To: Victor Ames <[v.ames@halvorsenmed.com]> Subject: Q3 accrual true-up before clo | F5: EMAIL | G5: =TRUE() | H5: EMAIL_PERSONAL | I5: medium | J5: =TRUE() | K5: redact | M5: =IF(G5="","added",IF((K5="redact")<>G5,"changed",""))
A6: E001 | B6: Finance & Accounting | C6: email.body | D6: Victor | E6: bject: Q3 accrual true-up before close [Victor], Before we close Q3 on Friday I need y | F6: PERSON | G6: =TRUE() | H6: PERSON | I6: medium | J6: =TRUE() | K6: redact | M6: =IF(G6="","added",IF((K6="redact")<>G6,"changed",""))
A7: E001 | B7: Finance & Accounting | C7: email.body | D7: $1.84M | E7: The warranty reserve needs to go up by [$1.84M] because of the infusion pump returns, a | F7: AMOUNT | G7: =TRUE() | H7: AMOUNT | I7: medium | J7: =TRUE() | K7: redact | M7: =IF(G7="","added",IF((K7="redact")<>G7,"changed",""))
A8: E001 | B8: Finance & Accounting | C8: email.body | D8: $620K | E8: ns, and the bonus accrual comes down by [$620K] now that we know sales will land at rou | F8: AMOUNT | G8: =TRUE() | H8: AMOUNT | I8: medium | J8: =TRUE() | K8: redact | M8: =IF(G8="","added",IF((K8="redact")<>G8,"changed",""))
A9: E001 | B9: Finance & Accounting | C9: email.body | D9: $212M | E9: that we know sales will land at roughly [$212M] for the quarter. Net impact to operatin | F9: AMOUNT | G9: =TRUE() | H9: AMOUNT | I9: medium | J9: =TRUE() | K9: redact | M9: =IF(G9="","added",IF((K9="redact")<>G9,"changed",""))
A10: E001 | B10: Finance & Accounting | C10: email.body | D10: -$1.22M | E10: rter. Net impact to operating income is [-$1.22M]. Raj on my team has the backup workboo | F10: AMOUNT | G10: =TRUE() | H10: AMOUNT | I10: medium | J10: =TRUE() | K10: redact | M10: =IF(G10="","added",IF((K10="redact")<>G10,"changed",""))
A11: E001 | B11: Finance & Accounting | C11: email.body | D11: Raj | E11: impact to operating income is -$1.22M. [Raj] on my team has the backup workbook if y | F11: PERSON | G11: =TRUE() | H11: PERSON | I11: medium | J11: =TRUE() | K11: redact | M11: =IF(G11="","added",IF((K11="redact")<>G11,"changed",""))
A12: E001 | B12: Finance & Accounting | C12: email.body | D12: Megan Ostrowski | E12: f you want to walk through it. Thanks, [Megan Ostrowski] Corporate Controller Office: (617) 555- | F12: PERSON | G12: =TRUE() | H12: PERSON | I12: medium | J12: =TRUE() | K12: redact | M12: =IF(G12="","added",IF((K12="redact")<>G12,"changed",""))
A13: E001 | B13: Finance & Accounting | C13: email.body | D13: (617) 555-0142 | E13: Ostrowski Corporate Controller Office: [(617) 555-0142] ext. 3310 | F13: PHONE | G13: =TRUE() | H13: PHONE_PERSONAL | I13: medium | J13: =TRUE() | K13: redact | M13: =IF(G13="","added",IF((K13="redact")<>G13,"changed",""))
A14: E001 | B14: Finance & Accounting | C14: email.body | D14: ext. 3310 | E14: orate Controller Office: (617) 555-0142 [ext. 3310] | F14: PHONE | H14: PHONE_PERSONAL | I14: medium | J14: =TRUE() | K14: redact | M14: =IF(G14="","added",IF((K14="redact")<>G14,"changed","")) | N14: Added in review. Extension of a named person's office line; v1 span stopped before it.
A15: E002 | B15: Finance & Accounting | C15: email.from.name | D15: Allison Grant | E15: From: [Allison Grant] <agrant@tidewaterrb.com> To: Victor Ame | F15: PERSON | G15: =TRUE() | H15: PERSON | I15: medium | J15: =TRUE() | K15: redact | M15: =IF(G15="","added",IF((K15="redact")<>G15,"changed",""))
A16: E002 | B16: Finance & Accounting | C16: email.from.address | D16: agrant@tidewaterrb.com | E16: From: Allison Grant <[agrant@tidewaterrb.com]> To: Victor Ames <vames@tidewaterrb.com | F16: EMAIL | G16: =TRUE() | H16: EMAIL_PERSONAL | I16: medium | J16: =TRUE() | K16: redact | M16: =IF(G16="","added",IF((K16="redact")<>G16,"changed",""))
A17: E002 | B17: Finance & Accounting | C17: email.to[0].name | D17: Victor Ames | E17: ison Grant <agrant@tidewaterrb.com> To: [Victor Ames] <vames@tidewaterrb.com> Subject: Wire a | F17: PERSON | G17: =TRUE() | H17: PERSON | I17: medium | J17: =TRUE() | K17: redact | M17: =IF(G17="","added",IF((K17="redact")<>G17,"changed",""))
A18: E002 | B18: Finance & Accounting | C18: email.to[0].address | D18: vames@tidewaterrb.com | E18: grant@tidewaterrb.com> To: Victor Ames <[vames@tidewaterrb.com]> Subject: Wire approval needed today - | F18: EMAIL | G18: =TRUE() | H18: EMAIL_PERSONAL | I18: medium | J18: =TRUE() | K18: redact | M18: =IF(G18="","added",IF((K18="redact")<>G18,"changed",""))
A19: E002 | B19: Finance & Accounting | C19: email.subject | D19: Castell Data Systems | E19: > Subject: Wire approval needed today - [Castell Data Systems] Hi Victor, Castell sent updated banki | F19: ORG | G19: =TRUE() | H19: ORG | I19: low | J19: =TRUE() | K19: redact | M19: =IF(G19="","added",IF((K19="redact")<>G19,"changed",""))
A20: E002 | B20: Finance & Accounting | C20: email.body | D20: Victor | E20: needed today - Castell Data Systems Hi [Victor], Castell sent updated banking details | F20: PERSON | G20: =TRUE() | H20: PERSON | I20: medium | J20: =TRUE() | K20: redact | M20: =IF(G20="","added",IF((K20="redact")<>G20,"changed",""))
A21: E002 | B21: Finance & Accounting | C21: email.body | D21: Castell | E21: day - Castell Data Systems Hi Victor, [Castell] sent updated banking details for the co | F21: ORG | G21: =TRUE() | H21: ORG | I21: low | J21: =TRUE() | K21: redact | M21: =IF(G21="","added",IF((K21="redact")<>G21,"changed",""))
A22: E002 | B22: Finance & Accounting | C22: email.body | D22: $250,000 | E22: ent. Treasury needs dual approval above [$250,000], and this one is $486,300.00. Benefici | F22: AMOUNT | G22: =TRUE() | H22: AMOUNT | I22: medium | J22: =TRUE() | K22: redact | M22: =IF(G22="","added",IF((K22="redact")<>G22,"changed",""))
A23: E002 | B23: Finance & Accounting | C23: email.body | D23: $486,300.00 | E23: pproval above $250,000, and this one is [$486,300.00]. Beneficiary: Castell Data Systems LLC | F23: AMOUNT | G23: =TRUE() | H23: AMOUNT | I23: medium | J23: =TRUE() | K23: redact | M23: =IF(G23="","added",IF((K23="redact")<>G23,"changed",""))
A24: E002 | B24: Finance & Accounting | C24: email.body | D24: Castell Data Systems LLC | E24: this one is $486,300.00. Beneficiary: [Castell Data Systems LLC] Bank: First Harborline Bank Routing (AB | F24: ORG | G24: =TRUE() | H24: ORG | I24: low | J24: =TRUE() | K24: redact | M24: =IF(G24="","added",IF((K24="redact")<>G24,"changed",""))
A25: E002 | B25: Finance & Accounting | C25: email.body | D25: 011000138 | E25: k: First Harborline Bank Routing (ABA): [011000138] Account: 4402 1187 9930 Reference: INV- | F25: FIN_ACCOUNT | G25: =TRUE() | H25: ACCOUNT_NUMBER | I25: high | J25: =TRUE() | K25: redact | M25: =IF(G25="","added",IF((K25="redact")<>G25,"changed",""))
A26: E002 | B26: Finance & Accounting | C26: email.body | D26: 4402 1187 9930 | E26: Bank Routing (ABA): 011000138 Account: [4402 1187 9930] Reference: INV-2026-0917 The account n | F26: FIN_ACCOUNT | G26: =TRUE() | H26: ACCOUNT_NUMBER | I26: high | J26: =TRUE() | K26: redact | M26: =IF(G26="","added",IF((K26="redact")<>G26,"changed",""))
A27: E002 | B27: Finance & Accounting | C27: email.body | D27: INV-2026-0917 | E27: 0138 Account: 4402 1187 9930 Reference: [INV-2026-0917] The account number is different from t | F27: ID_NUMBER | G27: =TRUE() | H27: ID_NUMBER | I27: high | J27: =FALSE() | K27: redact | M27: =IF(G27="","added",IF((K27="redact")<>G27,"changed",""))
A28: E002 | B28: Finance & Accounting | C28: email.body | D28: Joel Reyes | E28: d in June, so I called their AR contact [Joel Reyes] at (508) 555-0167 to confirm. He verifi | F28: PERSON | G28: =TRUE() | H28: PERSON | I28: medium | J28: =TRUE() | K28: redact | M28: =IF(G28="","added",IF((K28="redact")<>G28,"changed",""))
A29: E002 | B29: Finance & Accounting | C29: email.body | D29: (508) 555-0167 | E29: I called their AR contact Joel Reyes at [(508) 555-0167] to confirm. He verified it verbally. A | F29: PHONE | G29: =TRUE() | H29: PHONE_PERSONAL | I29: medium | J29: =TRUE() | K29: redact | M29: =IF(G29="","added",IF((K29="redact")<>G29,"changed",""))
A30: E002 | B30: Finance & Accounting | C30: email.body | D30: Allison | E30: 7 to confirm. He verified it verbally. [Allison] | F30: PERSON | G30: =TRUE() | H30: PERSON | I30: medium | J30: =TRUE() | K30: redact | M30: =IF(G30="","added",IF((K30="redact")<>G30,"changed",""))
A31: E003 | B31: Finance & Accounting | C31: email.from.name | D31: Hannah Liu | E31: From: [Hannah Liu] <hannah.liu@lumora.io> To: Tom Keller < | F31: PERSON | G31: =TRUE() | H31: PERSON | I31: medium | J31: =TRUE() | K31: redact | M31: =IF(G31="","added",IF((K31="redact")<>G31,"changed",""))
A32: E003 | B32: Finance & Accounting | C32: email.from.address | D32: hannah.liu@lumora.io | E32: From: Hannah Liu <[hannah.liu@lumora.io]> To: Tom Keller <tom@lumora.io> Subject | F32: EMAIL | G32: =TRUE() | H32: EMAIL_PERSONAL | I32: medium | J32: =TRUE() | K32: redact | M32: =IF(G32="","added",IF((K32="redact")<>G32,"changed",""))
A33: E003 | B33: Finance & Accounting | C33: email.to[0].name | D33: Tom Keller | E33: : Hannah Liu <hannah.liu@lumora.io> To: [Tom Keller] <tom@lumora.io> Subject: Fwd: ARR flash | F33: PERSON | G33: =TRUE() | H33: PERSON | I33: medium | J33: =TRUE() | K33: redact | M33: =IF(G33="","added",IF((K33="redact")<>G33,"changed",""))
A34: E003 | B34: Finance & Accounting | C34: email.to[0].address | D34: tom@lumora.io | E34: <hannah.liu@lumora.io> To: Tom Keller <[tom@lumora.io]> Subject: Fwd: ARR flash - September T | F34: EMAIL | G34: =TRUE() | H34: EMAIL_PERSONAL | I34: medium | J34: =TRUE() | K34: redact | M34: =IF(G34="","added",IF((K34="redact")<>G34,"changed",""))
A35: E003 | B35: Finance & Accounting | C35: email.body | D35: Tom | E35: o> Subject: Fwd: ARR flash - September [Tom], flagging before the board prep. See be | F35: PERSON | G35: =TRUE() | H35: PERSON | I35: medium | J35: =TRUE() | K35: redact | M35: =IF(G35="","added",IF((K35="redact")<>G35,"changed",""))
A36: E003 | B36: Finance & Accounting | C36: email.body | D36: Sam Petrakis | E36: ---- Forwarded message ---------- From: [Sam Petrakis] <spetrakis@lumora.io> To: Hannah Liu <h | F36: PERSON | G36: =TRUE() | H36: PERSON | I36: medium | J36: =TRUE() | K36: redact | M36: =IF(G36="","added",IF((K36="redact")<>G36,"changed",""))
A37: E003 | B37: Finance & Accounting | C37: email.body | D37: spetrakis@lumora.io | E37: message ---------- From: Sam Petrakis <[spetrakis@lumora.io]> To: Hannah Liu <hannah.liu@lumora.io> | F37: EMAIL | G37: =TRUE() | H37: EMAIL_PERSONAL | I37: medium | J37: =TRUE() | K37: redact | M37: =IF(G37="","added",IF((K37="redact")<>G37,"changed",""))
A38: E003 | B38: Finance & Accounting | C38: email.body | D38: Hannah Liu | E38: Sam Petrakis <spetrakis@lumora.io> To: [Hannah Liu] <hannah.liu@lumora.io> Hannah, Septemb | F38: PERSON | G38: =TRUE() | H38: PERSON | I38: medium | J38: =TRUE() | K38: redact | M38: =IF(G38="","added",IF((K38="redact")<>G38,"changed",""))
A39: E003 | B39: Finance & Accounting | C39: email.body | D39: hannah.liu@lumora.io | E39: s <spetrakis@lumora.io> To: Hannah Liu <[hannah.liu@lumora.io]> Hannah, September closed at $41.6M AR | F39: EMAIL | G39: =TRUE() | H39: EMAIL_PERSONAL | I39: medium | J39: =TRUE() | K39: redact | M39: =IF(G39="","added",IF((K39="redact")<>G39,"changed",""))
... A43: E003 | B43: Finance & Accounting | C43: email.body | D43: Two of our top ten logos, Brightline Health and Oakmont Freight, gave notice they will not renew in Q1. | E43: closed at $41.6M ARR vs plan of $44.0M. [Two of our top ten logos, Brightline Health and Oakmont Freight, gave notice they will not renew in Q1.] Net revenue retention dropped to 104% f | F43: FACT | G43: =TRUE() | H43: BUSINESS_CONFIDENTIAL | I43: high | J43: =TRUE() | K43: redact | M43: =IF(G43="","added",IF((K43="redact")<>G43,"changed",""))
...

Sheet Emails
A1: Email ID | B1: Area | C1: Industry | D1: Exec | E1: Task (purpose) | F1: Email text | G1: Spans | H1: To redact | I1: Changed or added | J1: Checked
A2: E001 | B2: Finance & Accounting | C2: Medical devices | D2: CFO | E2: Summarize this and tell me what I need to approve. | F2: From: Megan Ostrowski <m.ostrowski@halvorsenmed.com> To: Victor Ames <v.ames@halvorsenmed.com> Subject: Q3 accrual true-up before close Victor, Before we close Q3 on Friday I need your sign-off on two items. The warranty reserve needs to go up by $1.84M because of the infusion pump returns, and the bonus accrual comes down by $620K now that we know sales will land at roughly $212M for the quarter. Net impact to operating income is -$1.22M. Raj on my team has the backup workbook if you want to walk through it. Thanks, Megan Ostrowski Corporate Controller Office: (617) 555-0142 ext. 3310 | G2: =COUNTIF(Spans!$A:$A,A2) | H2: =COUNTIFS(Spans!$A:$A,A2,Spans!$K:$K,"redact") | I2: =COUNTIFS(Spans!$A:$A,A2,Spans!$M:$M,"changed")+COUNTIFS(Spans!$A:$A,A2,Spans!$M:$M,"added") | J2: =G2-COUNTIFS(Spans!$A:$A,A2,Spans!$L:$L,"")
A3: E002 | B3: Finance & Accounting | C3: Banking | D3: CFO | E3: Is this wire request legitimate? Draft a reply approving it if it looks fine. | F3: From: Allison Grant <agrant@tidewaterrb.com> To: Victor Ames <vames@tidewaterrb.com> Subject: Wire approval needed today - Castell Data Systems Hi Victor, Castell sent updated banking details for the core system license payment. Treasury needs dual approval above $250,000, and this one is $486,300.00. Beneficiary: Castell Data Systems LLC Bank: First Harborline Bank Routing (ABA): 011000138 Account: 4402 1187 9930 Reference: INV-2026-0917 The account number is different from the one we paid in June, so I called their AR contact Joel Reyes at (508) 555-0167 to confirm. He verified it verbally. Allison | G3: =COUNTIF(Spans!$A:$A,A3) | H3: =COUNTIFS(Spans!$A:$A,A3,Spans!$K:$K,"redact") | I3: =COUNTIFS(Spans!$A:$A,A3,Spans!$M:$M,"changed")+COUNTIFS(Spans!$A:$A,A3,Spans!$M:$M,"added") | J3: =G3-COUNTIFS(Spans!$A:$A,A3,Spans!$L:$L,"")
A4: E003 | B4: Finance & Accounting | C4: Software (SaaS) | D4: CEO | E4: Summarize this thread in three bullet points. | F4: From: Hannah Liu <hannah.liu@lumora.io> To: Tom Keller <tom@lumora.io> Subject: Fwd: ARR flash - September Tom, flagging before the board prep. See below. ---------- Forwarded message ---------- From: Sam Petrakis <spetrakis@lumora.io> To: Hannah Liu <hannah.liu@lumora.io> Hannah, September closed at $41.6M ARR vs plan of $44.0M. Two of our top ten logos, Brightline Health and Oakmont Freight, gave notice they will not renew in Q1. Net revenue retention dropped to 104% from 112% last quarter. Sam | G4: =COUNTIF(Spans!$A:$A,A4) | H4: =COUNTIFS(Spans!$A:$A,A4,Spans!$K:$K,"redact") | I4: =COUNTIFS(Spans!$A:$A,A4,Spans!$M:$M,"changed")+COUNTIFS(Spans!$A:$A,A4,Spans!$M:$M,"added") | J4: =G4-COUNTIFS(Spans!$A:$A,A4,Spans!$L:$L,"")
A5: E004 | B5: Finance & Accounting | C5: Retail | D5: General Counsel | E5: Approve my expense report if the totals match. | F5: From: Concur Expense <no-reply@expense.marlowfinch.com> To: Grace Holloway <gholloway@marlowfinch.com> Subject: Expense report ER-88213 ready for submission Report: ER-88213 - Chicago outside counsel meetings Employee: Grace Holloway (ID E104577) Card: Corporate Amex ending in 3008 Hotel - The Langham Chicago (3 nights) $1,284.60 Dinner with R. Mendel (Keane Porter LLP) $412.18 Airfare ORD round trip $687.40 Total $2,384.18 Questions? Contact the Expense Help Desk at 1-800-555-0100. | G5: =COUNTIF(Spans!$A:$A,A5) | H5: =COUNTIFS(Spans!$A:$A,A5,Spans!$K:$K,"redact") | I5: =COUNTIFS(Spans!$A:$A,A5,Spans!$M:$M,"changed")+COUNTIFS(Spans!$A:$A,A5,Spans!$M:$M,"added") | J5: =G5-COUNTIFS(Spans!$A:$A,A5,Spans!$L:$L,"")
A6: E005 | B6: Finance & Accounting | C6: Energy | D6: CFO | E6: What are the auditors asking for and when is it due? | F6: From: Owen Fairbanks <ofairbanks@brightwaterhale.com> To: Nadia Kurz <nkurz@pinecrestenergy.com> Subject: Interim audit PBC list - items outstanding Nadia, We're still missing three items from the interim PBC list: 1. September bank statements for the operating account ending 7731 and the payroll account ending 2206 2. The impairment memo for the Big Sandy well field 3. Board minutes from the August special session approving the sale of the midstream assets We need these by October 3 to stay on schedule. My cell is (713) 555-0118 if easier to talk. Best, Owen Fairbanks, Senior Manager Brightwater & Hale LLP | G6: =COUNTIF(Spans!$A:$A,A6) | H6: =COUNTIFS(Spans!$A:$A,A6,Spans!$K:$K,"redact") | I6: =COUNTIFS(Spans!$A:$A,A6,Spans!$M:$M,"changed")+COUNTIFS(Spans!$A:$A,A6,Spans!$M:$M,"added") | J6: =G6-COUNTIFS(Spans!$A:$A,A6,Spans!$L:$L,"")
A7: E006 | B7: Finance & Accounting | C7: Healthcare | D7: COO | E7: Pull out the invoice total and due date. | F7: From: Sofie Lindqvist <sofie.lindqvist@nordbergclinical.se> To: Priya Raman <praman@stellanhealth.com> Subject: Invoice 2026-448 attached Hello Priya, please find the invoice below (text copied from PDF). NORDBERG CLINICAL AB | Invoice No. 2026-448 Bill to: Stellan Health Partners, 1200 Harbor Point Blvd, Suite 400, Baltimore, MD 21224 Service: Site monitoring, study STL-Aurora, Phase II, Aug 2026 Amount due: EUR 78,450.00 Due date: 15 October 2026 IBAN: SE45 5000 0000 0583 9825 7466 BIC: ESSESESS Kind regards, Sofie Lindqvist +46 8 555 012 34 | G7: =COUNTIF(Spans!$A:$A,A7) | H7: =COUNTIFS(Spans!$A:$A,A7,Spans!$K:$K,"redact") | I7: =COUNTIFS(Spans!$A:$A,A7,Spans!$M:$M,"changed")+COUNTIFS(Spans!$A:$A,A7,Spans!$M:$M,"added") | J7: =G7-COUNTIFS(Spans!$A:$A,A7,Spans!$L:$L,"")
A8: E007 | B8: Finance & Accounting | C8: Logistics | D8: COO | E8: Anything here I need to act on? | F8: From: Harborline Bank Treasury Insights <insights@harborlinebank.com> To: Treasury Subscribers Subject: Rate outlook: what the September decision means for corporate cash The Federal Reserve held rates steady at its September meeting. Our economists now expect one cut before year end, which could lower yields on money market sweep products by 15 to 25 basis points. Three steps treasury teams are considering: - Laddering short-term Treasuries out to 12 months - Reviewing sweep thresholds with your relationship manager - Revisiting FX hedges ahead of Q4 volatility Read the full outlook at harborlinebank.com/insights. Questions? Call our Treasury Desk at 1-888-555-0123. You are receiving this because you subscribed to Treasury Insights. Unsubscribe anytime. | G8: =COUNTIF(Spans!$A:$A,A8) | H8: =COUNTIFS(Spans!$A:$A,A8,Spans!$K:$K,"redact") | I8: =COUNTIFS(Spans!$A:$A,A8,Spans!$M:$M,"changed")+COUNTIFS(Spans!$A:$A,A8,Spans!$M:$M,"added") | J8: =G8-COUNTIFS(Spans!$A:$A,A8,Spans!$L:$L,"")
A9: E008 | B9: Finance & Accounting | C9: Software (SaaS) | D9: CEO | E9: How bad is this and what are my options? | F9: From: Hannah Liu <hannah.liu@lumora.io> To: Tom Keller <tom@lumora.io> Subject: Payroll funding for Oct 15 - need a decision Tom, Heads up that we will not have enough cash to fund the October 15 payroll without drawing on the revolver. Payroll is $3.9M, operating cash is $2.7M, and the Delmar Freight receivable of $1.6M is now 45 days late. Options: 1. Draw $2M on the Silvergate Commercial line (covenant headroom is thin) 2. Delay vendor payments by two weeks 3. Ask Marcus to push the Series C bridge forward Let's talk today. Hannah | G9: =COUNTIF(Spans!$A:$A,A9) | H9: =COUNTIFS(Spans!$A:$A,A9,Spans!$K:$K,"redact") | I9: =COUNTIFS(Spans!$A:$A,A9,Spans!$M:$M,"changed")+COUNTIFS(Spans!$A:$A,A9,Spans!$M:$M,"added") | J9: =G9-COUNTIFS(Spans!$A:$A,A9,Spans!$L:$L,"")
A10: E009 | B10: Legal & Compliance | C10: Retail | D10: General Counsel | E10: Summarize this and list what our team needs to do. | F10: From: Daniel Whitcomb <dwhitcomb@keaneporter.com> To: Grace Holloway <gholloway@marlowfinch.com> Subject: Litigation hold - Ferreira v. Marlow & Finch Grace, Following service of the complaint in Ferreira v. Marlow & Finch Retail, Inc., Case No. 1:26-cv-04418 (N.D. Ill.), please issue a litigation hold to the custodians below today: - Kevin Tran, Regional Director, Midwest - Lisa Morrow, Store Manager, Store #0412 - Ben Adeyemi, HR Business Partner The plaintiff alleges she was terminated three weeks after reporting a wage-and-hour violation. Our early read is that exposure is in the $400K to $750K range. Daniel Whitcomb Keane Porter LLP | (312) 555-0174 | G10: =COUNTIF(Spans!$A:$A,A10) | H10: =COUNTIFS(Spans!$A:$A,A10,Spans!$K:$K,"redact") | I10: =COUNTIFS(Spans!$A:$A,A10,Spans!$M:$M,"changed")+COUNTIFS(Spans!$A:$A,A10,Spans!$M:$M,"added") | J10: =G10-COUNTIFS(Spans!$A:$A,A10,Spans!$L:$L,"")
A11: E010 | B11: Legal & Compliance | C11: Software (SaaS) | D11: CEO | E11: Tell me which redlines are deal breakers. | F11: From: Ivy Castellanos <icastellanos@lumora.io> To: Tom Keller <tom@lumora.io> Subject: Project Kestrel - mutual NDA redlines back from Arcwell Tom, Arcwell Systems returned the NDA for Kestrel. Main changes: 1. They struck the non-solicit on our engineers. I want that back in. 2. Term shortened from 3 years to 18 months. 3. They added a residuals clause, which would let them use anything their team "remembers." This is the one I'd fight hardest. Their GC, Martin Oyelaran, wants to close by Wednesday. I'm free after 2pm. Ivy | G11: =COUNTIF(Spans!$A:$A,A11) | H11: =COUNTIFS(Spans!$A:$A,A11,Spans!$K:$K,"redact") | I11: =COUNTIFS(Spans!$A:$A,A11,Spans!$M:$M,"changed")+COUNTIFS(Spans!$A:$A,A11,Spans!$M:$M,"added") | J11: =G11-COUNTIFS(Spans!$A:$A,A11,Spans!$L:$L,"")
A12: E011 | B12: Legal & Compliance | C12: Manufacturing | D12: CEO | E12: Is this invoice in line with the budget we agreed? | F12: From: Billing <billing@strandlawgroup.com> To: Laura Brennan <lbrennan@halvorsenmed.com> Subject: Statement for services - Matter 20417-003 Dear Ms. Brennan, Enclosed is our statement for August on Matter 20417-003 (FDA warning letter response, Reno facility). Partner time (E. Strand), 42.5 hrs $46,750.00 Associate time, 118.0 hrs $64,900.00 Regulatory consultant $18,200.00 Total this period $129,850.00 Budget to date: $300,000. Billed to date: $271,340. Payment instructions are on file. Thank you. | G12: =COUNTIF(Spans!$A:$A,A12) | H12: =COUNTIFS(Spans!$A:$A,A12,Spans!$K:$K,"redact") | I12: =COUNTIFS(Spans!$A:$A,A12,Spans!$M:$M,"changed")+COUNTIFS(Spans!$A:$A,A12,Spans!$M:$M,"added") | J12: =G12-COUNTIFS(Spans!$A:$A,A12,Spans!$L:$L,"")
A13: E012 | B13: Legal & Compliance | C13: Banking | D13: CFO | E13: Summarize what the regulator is asking and draft a holding reply. | F13: From: Theresa Nguyen <tnguyen@tidewaterrb.com> To: Victor Ames <vames@tidewaterrb.com> Subject: OCC information request - response due Oct 10 Victor, We received a supervisory letter from the Office of the Comptroller of the Currency this morning. They are requesting all documentation on the 2025 overdraft fee reversal program, including the customer remediation list of about 14,200 accounts. The examiner in charge is Robert Haines. I'd like to send an acknowledgment today and propose a call next week. Our outside counsel at Pell Whitaker is already looped in. Theresa Chief Compliance Officer | G13: =COUNTIF(Spans!$A:$A,A13) | H13: =COUNTIFS(Spans!$A:$A,A13,Spans!$K:$K,"redact") | I13: =COUNTIFS(Spans!$A:$A,A13,Spans!$M:$M,"changed")+COUNTIFS(Spans!$A:$A,A13,Spans!$M:$M,"added") | J13: =G13-COUNTIFS(Spans!$A:$A,A13,Spans!$L:$L,"")
... A101: E100 | B101: Adversarial & Evasion | C101: Consumer goods | D101: CEO | E101: Summarize the attached notes. | F101: From: Chloe Bennett <cbennett@fernwoodhome.com> To: Alan Pierce <apierce@fernwoodhome.com> Subject: Notes from the scanned contract Alan, the OCR on the old distributor contract is messy but here's what I pulled: Distributor: Harrovv Home Supply (OCR read the w as vv) Signed by: R0bert Kline, contact rkl1ne@harrowhomesupp1y.com Tax ID: 8 7-4 4 1 9 0 2 6 Minimum annual purchase: $1.2 million Clause 14 gives them exclusivity in the Pacific Northwest until 2028, which blocks the Target deal there. Chloe | G101: =COUNTIF(Spans!$A:$A,A101) | H101: =COUNTIFS(Spans!$A:$A,A101,Spans!$K:$K,"redact") | I101: =COUNTIFS(Spans!$A:$A,A101,Spans!$M:$M,"changed")+COUNTIFS(Spans!$A:$A,A101,Spans!$M:$M,"added") | J101: =G101-COUNTIFS(Spans!$A:$A,A101,Spans!$L:$L,"")
